<?xml version='1.0' encoding='utf-8'?>
<mujoco model="DR02-S">
  <compiler angle="radian" meshdir="../assets" />

  <asset>
    <mesh name="base_link" file="base_link.STL" />
    <mesh name="body" file="body.STL" />
    <mesh name="left_shoulder_y_link" file="left_shoulder_y_link.STL" />
    <mesh name="left_shoulder_x_link" file="left_shoulder_x_link.STL" />
    <mesh name="left_shoulder_z_link" file="left_shoulder_z_link.STL" />
    <mesh name="left_elbow_link" file="left_elbow_link.STL" />
    <mesh name="right_shoulder_y_link" file="right_shoulder_y_link.STL" />
    <mesh name="right_shoulder_x_link" file="right_shoulder_x_link.STL" />
    <mesh name="right_shoulder_z_link" file="right_shoulder_z_link.STL" />
    <mesh name="right_elbow_link" file="right_elbow_link.STL" />
    <mesh name="left_hip_y_link" file="left_hip_y_link.STL" />
    <mesh name="left_hip_x_link" file="left_hip_x_link.STL" />
    <mesh name="left_hip_z_link" file="left_hip_z_link.STL" />
    <mesh name="left_knee_link" file="left_knee_link.STL" />
    <mesh name="left_ankle_y_link" file="left_ankle_y_link.STL" />
    <mesh name="left_ankle_x_link" file="left_ankle_x_link.STL" />
    <mesh name="right_hip_y_link" file="right_hip_y_link.STL" />
    <mesh name="right_hip_x_link" file="right_hip_x_link.STL" />
    <mesh name="right_hip_z_link" file="right_hip_z_link.STL" />
    <mesh name="right_knee_link" file="right_knee_link.STL" />
    <mesh name="right_ankle_y_link" file="right_ankle_y_link.STL" />
    <mesh name="right_ankle_x_link" file="right_ankle_x_link.STL" />
  </asset>

  <worldbody>
    <body name="base_link">
      <freejoint name="root" /><inertial pos="9.3e-05 6e-06 0.013442" quat="0.706621 0.70714 0.0181893 -0.0175526" mass="8.06269" diaginertia="0.0478262 0.0379779 0.034616" />
      <geom type="mesh" contype="0" conaffinity="0" group="1" density="0" rgba="0.75294 0.75294 0.75294 1" mesh="base_link" />
      <geom name="base_link_collision" size="0.09 0.085" quat="0.707107 0.707107 0 0" type="cylinder" rgba="0.75294 0.75294 0.75294 1" />
      <body name="body" pos="0 0 0.29">
        <site name="body_imu" pos="0 0 0.18" size="0.015" rgba="0.1 0.6 1 1" group="3" /><inertial pos="-0.02277 0.004208 0.185037" quat="0.715956 -0.0136239 -0.000497459 0.698013" mass="21.3372" diaginertia="0.598309 0.556305 0.184396" />
        <joint name="waist_z_joint" pos="0 0 0" axis="0 0 1" range="-1.7453 3.6652" actuatorfrcrange="-137 137" damping="8" armature="0.02" />
        <geom type="mesh" contype="0" conaffinity="0" group="1" density="0" rgba="0.75294 0.75294 0.75294 1" mesh="body" />
        <geom name="body_pelvis_collision" size="0.075 0.075 0.06" pos="0 0 -0.13" type="box" rgba="0.75294 0.75294 0.75294 1" />
        <geom name="body_waist_collision" size="0.11 0.12 0.05" pos="-0.01 0 0" type="box" rgba="0.75294 0.75294 0.75294 1" />
        <geom name="body_torso_collision" size="0.125 0.125 0.13" pos="0 0 0.2" type="box" rgba="0.75294 0.75294 0.75294 1" />
        <geom name="body_neck_collision" size="0.05 0.03" pos="-0.02 0 0.37" type="cylinder" rgba="0.75294 0.75294 0.75294 1" />
        <geom name="body_head_collision" size="0.12" pos="0 0 0.5" rgba="0.75294 0.75294 0.75294 1" />
        <body name="left_shoulder_y_link" pos="-0.02 0.22315 0.2349">
          <inertial pos="0.001479 -0.014833 0.000165" quat="0.535109 0.551574 -0.443626 0.461108" mass="1.40044" diaginertia="0.00199718 0.00199195 0.00101788" />
          <joint name="left_shoulder_y_joint" pos="0 0 0" axis="0 1 0" range="-3.8397 1.5708" actuatorfrcrange="-137 137" damping="8" armature="0.02" />
          <geom type="mesh" contype="0" conaffinity="0" group="1" density="0" rgba="0.75294 0.75294 0.75294 1" mesh="left_shoulder_y_link" />
          <body name="left_shoulder_x_link">
            <inertial pos="0.000432 0 -0.048362" quat="0.532489 0.465248 0.465248 0.532489" mass="0.697075" diaginertia="0.002243 0.00160154 0.00157146" />
            <joint name="left_shoulder_x_joint" pos="0 0 0" axis="1 0 0" range="-0.349066 3.49066" actuatorfrcrange="-137 137" damping="8" armature="0.02" />
            <geom type="mesh" contype="0" conaffinity="0" group="1" density="0" rgba="0.75294 0.75294 0.75294 1" mesh="left_shoulder_x_link" />
            <geom name="left_shoulder_x_upper_collision" size="0.055 0.0275" pos="0 0 -0.09" type="cylinder" rgba="0.75294 0.75294 0.75294 1" />
            <geom name="left_shoulder_x_joint_collision" size="0.055 0.055" quat="0.707107 0 0.707107 0" type="cylinder" rgba="0.75294 0.75294 0.75294 1" />
            <body name="left_shoulder_z_link" pos="0 0 -0.265">
              <inertial pos="-0.00426 -0.0003 0.094408" quat="0.999326 0.00651409 -0.0341538 0.0118128" mass="1.72093" diaginertia="0.00613971 0.00580856 0.00193173" />
              <joint name="left_shoulder_z_joint" pos="0 0 0" axis="0 0 1" range="-2.9671 2.9671" actuatorfrcrange="-137 137" damping="8" armature="0.02" />
              <geom type="mesh" contype="0" conaffinity="0" group="1" density="0" rgba="0.75294 0.75294 0.75294 1" mesh="left_shoulder_z_link" />
              <geom name="left_shoulder_z_collision" size="0.057 0.02" pos="-0.005 0 0.08" type="cylinder" rgba="0.75294 0.75294 0.75294 1" />
              <body name="left_elbow_link" quat="0.707105 0 -0.707108 0">
                <inertial pos="5.5e-05 0.000466 -0.101685" quat="0.938053 0.00116829 -0.000602952 0.346488" mass="1.71097" diaginertia="0.0354123 0.0353879 0.00129576" />
                <joint name="left_elbow_joint" pos="0 0 0" axis="0 1 0" range="-0.767945 1.74533" actuatorfrcrange="-137 137" damping="8" armature="0.02" />
                <geom type="mesh" contype="0" conaffinity="0" group="1" density="0" rgba="0.75294 0.75294 0.75294 1" mesh="left_elbow_link" />
                <geom name="left_elbow_joint_collision" size="0.055 0.055" quat="0.707107 0.707107 0 0" type="cylinder" rgba="0.75294 0.75294 0.75294 1" />
                <geom name="left_elbow_forearm_collision" size="0.045 0.11" pos="0 0 -0.17" type="cylinder" rgba="0.75294 0.75294 0.75294 1" />
                <geom name="left_elbow_hand_collision" size="0.045" pos="0 0 -0.34" rgba="0.75294 0.75294 0.75294 1" />
              </body>
            </body>
          </body>
        </body>
        <body name="right_shoulder_y_link" pos="-0.02 -0.22315 0.2349">
          <inertial pos="0.001479 0.014833 -0.000165" quat="0.461108 0.443626 -0.551574 0.535109" mass="1.40044" diaginertia="0.00199718 0.00199195 0.00101788" />
          <joint name="right_shoulder_y_joint" pos="0 0 0" axis="0 1 0" range="-3.8397 1.5708" actuatorfrcrange="-137 137" damping="8" armature="0.02" />
          <geom type="mesh" contype="0" conaffinity="0" group="1" density="0" rgba="0.75294 0.75294 0.75294 1" mesh="right_shoulder_y_link" />
          <body name="right_shoulder_x_link">
            <inertial pos="0.000432 0 -0.048362" quat="0.532489 0.465248 0.465248 0.532489" mass="0.697075" diaginertia="0.002243 0.00160154 0.00157146" />
            <joint name="right_shoulder_x_joint" pos="0 0 0" axis="1 0 0" range="-3.49066 0.349066" actuatorfrcrange="-137 137" damping="8" armature="0.02" />
            <geom type="mesh" contype="0" conaffinity="0" group="1" density="0" rgba="0.752941 0.752941 0.752941 1" mesh="right_shoulder_x_link" />
            <geom name="right_shoulder_x_upper_collision" size="0.055 0.0275" pos="0 0 -0.09" type="cylinder" rgba="0.752941 0.752941 0.752941 1" />
            <geom name="right_shoulder_x_joint_collision" size="0.055 0.055" quat="0.707107 0 0.707107 0" type="cylinder" rgba="0.752941 0.752941 0.752941 1" />
            <body name="right_shoulder_z_link" pos="0 0 -0.265">
              <inertial pos="-0.00426 -0.0003 0.094408" quat="0.999326 0.00651409 -0.0341538 0.0118128" mass="1.72093" diaginertia="0.00613971 0.00580856 0.00193173" />
              <joint name="right_shoulder_z_joint" pos="0 0 0" axis="0 0 1" range="-2.9671 2.9671" actuatorfrcrange="-137 137" damping="8" armature="0.02" />
              <geom type="mesh" contype="0" conaffinity="0" group="1" density="0" rgba="0.752941 0.752941 0.752941 1" mesh="right_shoulder_z_link" />
              <geom name="right_shoulder_z_collision" size="0.057 0.02" pos="-0.005 0 0.08" type="cylinder" rgba="0.752941 0.752941 0.752941 1" />
              <body name="right_elbow_link" quat="0.707105 0 -0.707108 0">
                <inertial pos="5.5e-05 0.000466 -0.101685" quat="0.938053 0.00116829 -0.000602952 0.346488" mass="1.71097" diaginertia="0.0354123 0.0353879 0.00129576" />
                <joint name="right_elbow_joint" pos="0 0 0" axis="0 1 0" range="-0.767945 1.74533" actuatorfrcrange="-137 137" damping="8" armature="0.02" />
                <geom type="mesh" contype="0" conaffinity="0" group="1" density="0" rgba="0.752941 0.752941 0.752941 1" mesh="right_elbow_link" />
                <geom name="right_elbow_joint_collision" size="0.055 0.055" quat="0.707107 0.707107 0 0" type="cylinder" rgba="0.752941 0.752941 0.752941 1" />
                <geom name="right_elbow_forearm_collision" size="0.045 0.11" pos="0 0 -0.17" type="cylinder" rgba="0.752941 0.752941 0.752941 1" />
                <geom name="right_elbow_hand_collision" size="0.045" pos="0 0 -0.34" rgba="0.752941 0.752941 0.752941 1" />
              </body>
            </body>
          </body>
        </body>
      </body>
      <body name="left_hip_y_link" pos="0 0.1614 0">
        <inertial pos="0.004243 -0.007887 0.001484" quat="0.129351 0.485332 -0.638265 0.583386" mass="2.63319" diaginertia="0.00579908 0.00555755 0.00529138" />
        <joint name="left_hip_y_joint" pos="0 0 0" axis="0 1 0" range="-2.7925 1.5708" actuatorfrcrange="-363 363" damping="8" armature="0.02" />
        <geom type="mesh" contype="0" conaffinity="0" group="1" density="0" rgba="0.752941 0.752941 0.752941 1" mesh="left_hip_y_link" />
        <geom name="left_hip_y_collision" size="0.07 0.0675" quat="0.707107 0 0.707107 0" type="cylinder" rgba="0.752941 0.752941 0.752941 1" />
        <body name="left_hip_x_link">
          <inertial pos="0.001042 0.00317 -0.074161" quat="0.691853 -0.153969 -0.143586 0.690663" mass="1.13151" diaginertia="0.00586944 0.00420414 0.00385442" />
          <joint name="left_hip_x_joint" pos="0 0 0" axis="1 0 0" range="-0.349066 2.618" actuatorfrcrange="-363 363" damping="8" armature="0.02" />
          <geom type="mesh" contype="0" conaffinity="0" group="1" density="0" rgba="0.752941 0.752941 0.752941 1" mesh="left_hip_x_link" />
          <body name="left_hip_z_link" pos="0 0 -0.1282">
            <inertial pos="0.008747 -0.002664 -0.111374" quat="0.999131 0.0295497 0.0291442 0.00393055" mass="2.68437" diaginertia="0.0302007 0.0285869 0.00748542" />
            <joint name="left_hip_z_joint" pos="0 0 0" axis="0 0 1" range="-0.5236 3.6652" actuatorfrcrange="-137 137" damping="8" armature="0.02" />
            <geom type="mesh" contype="0" conaffinity="0" group="1" density="0" rgba="0.752941 0.752941 0.752941 1" mesh="left_hip_z_link" />
            <geom name="left_hip_z_collision" size="0.07 0.11" pos="0 0 -0.115" type="cylinder" rgba="0.752941 0.752941 0.752941 1" />
            <body name="left_knee_link" pos="0 0 -0.2912">
              <inertial pos="-0.004924 -0.001316 -0.092649" quat="0.99983 -0.00969714 -0.0151271 0.00424973" mass="4.24665" diaginertia="0.0878984 0.0870418 0.00921174" />
              <joint name="left_knee_joint" pos="0 0 0" axis="0 1 0" range="-0.17453 2.4958" actuatorfrcrange="-363 363" damping="8" armature="0.02" />
              <geom type="mesh" contype="0" conaffinity="0" group="1" density="0" rgba="0.752941 0.752941 0.752941 1" mesh="left_knee_link" />
              <geom name="left_knee_joint_collision" size="0.06 0.07" quat="0.707107 0.707107 0 0" type="cylinder" rgba="0.752941 0.752941 0.752941 1" />
              <geom name="left_knee_shin_collision" size="0.06 0.14" pos="-0.02 0 -0.21" type="cylinder" rgba="0.752941 0.752941 0.752941 1" />
              <body name="left_ankle_y_link" pos="0 0 -0.41">
                <inertial pos="0.000479 0.003282 0.000327" quat="-0.0255077 0.708777 0.00920828 0.704911" mass="1.37783" diaginertia="0.00190608 0.00177252 0.0015284" />
                <joint name="left_ankle_y_joint" pos="0 0 0" axis="0 1 0" range="-1.0472 0.7854" actuatorfrcrange="-137 137" damping="8" armature="0.02" />
                <geom type="mesh" contype="0" conaffinity="0" group="1" density="0" rgba="0.752941 0.752941 0.752941 1" mesh="left_ankle_y_link" />
                <geom name="left_ankle_y_collision" size="0.044 0.055" quat="0.707107 0.707107 0 0" type="cylinder" rgba="0.752941 0.752941 0.752941 1" />
                <body name="left_ankle_x_link">
                  <inertial pos="0.046836 6.8e-05 -0.032705" quat="0.476848 0.522612 0.519885 0.478761" mass="1.48475" diaginertia="0.00862101 0.00812021 0.00238478" />
                  <joint name="left_ankle_x_joint" pos="0 0 0" axis="1 0 0" range="-0.61087 0.61087" actuatorfrcrange="-50 50" damping="8" armature="0.02" />
                  <geom type="mesh" contype="0" conaffinity="0" group="1" density="0" rgba="0.752941 0.752941 0.752941 1" mesh="left_ankle_x_link" />
                  <site name="left_foot" pos="0.045 0 -0.075" size="0.015" rgba="0.1 0.8 0.1 1" group="3" />
                  <geom name="left_foot_collision" size="0.15 0.055 0.03" pos="0.045 0 -0.045" type="box" rgba="0.752941 0.752941 0.752941 1" />
                </body>
              </body>
            </body>
          </body>
        </body>
      </body>
      <body name="right_hip_y_link" pos="0 -0.1614 0">
        <inertial pos="-0.004243 0.007887 0.001484" quat="0.638265 0.583386 -0.129351 0.485332" mass="2.63319" diaginertia="0.00579908 0.00555755 0.00529138" />
        <joint name="right_hip_y_joint" pos="0 0 0" axis="0 1 0" range="-2.7925 1.5708" actuatorfrcrange="-363 363" damping="8" armature="0.02" />
        <geom type="mesh" contype="0" conaffinity="0" group="1" density="0" rgba="0.752941 0.752941 0.752941 1" mesh="right_hip_y_link" />
        <geom name="right_hip_y_collision" size="0.07 0.0675" quat="0.707107 0 0.707107 0" type="cylinder" rgba="0.752941 0.752941 0.752941 1" />
        <body name="right_hip_x_link">
          <inertial pos="-0.001042 -0.00317 -0.074161" quat="0.691853 0.153969 0.143586 0.690663" mass="1.13151" diaginertia="0.00586944 0.00420414 0.00385442" />
          <joint name="right_hip_x_joint" pos="0 0 0" axis="1 0 0" range="-2.618 0.349066" actuatorfrcrange="-363 363" damping="8" armature="0.02" />
          <geom type="mesh" contype="0" conaffinity="0" group="1" density="0" rgba="0.752941 0.752941 0.752941 1" mesh="right_hip_x_link" />
          <body name="right_hip_z_link" pos="0 0 -0.1282">
            <inertial pos="0.008747 -0.002664 -0.111374" quat="0.999131 0.0295497 0.0291442 0.00393055" mass="2.68437" diaginertia="0.0302007 0.0285869 0.00748542" />
            <joint name="right_hip_z_joint" pos="0 0 0" axis="0 0 1" range="-3.6652 0.5236" actuatorfrcrange="-137 137" damping="8" armature="0.02" />
            <geom type="mesh" contype="0" conaffinity="0" group="1" density="0" rgba="0.752941 0.752941 0.752941 1" mesh="right_hip_z_link" />
            <geom name="right_hip_z_collision" size="0.07 0.11" pos="0 0 -0.115" type="cylinder" rgba="0.752941 0.752941 0.752941 1" />
            <body name="right_knee_link" pos="0 0 -0.2912">
              <inertial pos="-0.004924 -0.001316 -0.092649" quat="0.99983 -0.00969714 -0.0151271 0.00424973" mass="4.24665" diaginertia="0.0878984 0.0870418 0.00921174" />
              <joint name="right_knee_joint" pos="0 0 0" axis="0 1 0" range="-0.17453 2.4958" actuatorfrcrange="-363 363" damping="8" armature="0.02" />
              <geom type="mesh" contype="0" conaffinity="0" group="1" density="0" rgba="0.752941 0.752941 0.752941 1" mesh="right_knee_link" />
              <geom name="right_knee_joint_collision" size="0.06 0.07" quat="0.707107 0.707107 0 0" type="cylinder" rgba="0.752941 0.752941 0.752941 1" />
              <geom name="right_knee_shin_collision" size="0.06 0.14" pos="-0.02 0 -0.21" type="cylinder" rgba="0.752941 0.752941 0.752941 1" />
              <body name="right_ankle_y_link" pos="0 0 -0.41">
                <inertial pos="0.000479 0.003282 0.000327" quat="-0.0255077 0.708777 0.00920828 0.704911" mass="1.37783" diaginertia="0.00190608 0.00177252 0.0015284" />
                <joint name="right_ankle_y_joint" pos="0 0 0" axis="0 1 0" range="-1.0472 0.7854" actuatorfrcrange="-137 137" damping="8" armature="0.02" />
                <geom type="mesh" contype="0" conaffinity="0" group="1" density="0" rgba="0.752941 0.752941 0.752941 1" mesh="right_ankle_y_link" />
                <geom name="right_ankle_y_collision" size="0.044 0.055" quat="0.707107 0.707107 0 0" type="cylinder" rgba="0.752941 0.752941 0.752941 1" />
                <body name="right_ankle_x_link">
                  <inertial pos="0.046836 6.8e-05 -0.032705" quat="0.476848 0.522612 0.519885 0.478761" mass="1.48475" diaginertia="0.00862101 0.00812021 0.00238478" />
                  <joint name="right_ankle_x_joint" pos="0 0 0" axis="1 0 0" range="-0.61087 0.61087" actuatorfrcrange="-50 50" damping="8" armature="0.02" />
                  <geom type="mesh" contype="0" conaffinity="0" group="1" density="0" rgba="0.752941 0.752941 0.752941 1" mesh="right_ankle_x_link" />
                  <site name="right_foot" pos="0.045 0 -0.075" size="0.015" rgba="0.1 0.8 0.1 1" group="3" />
                  <geom name="right_foot_collision" size="0.15 0.055 0.03" pos="0.045 0 -0.045" type="box" rgba="0.752941 0.752941 0.752941 1" />
                </body>
              </body>
            </body>
          </body>
        </body>
      </body>
    </body>
  </worldbody>
<actuator><position name="waist_z_joint_position" joint="waist_z_joint" kp="800" ctrllimited="true" ctrlrange="-1.7453 3.6652" /><position name="left_shoulder_y_joint_position" joint="left_shoulder_y_joint" kp="800" ctrllimited="true" ctrlrange="-3.8397 1.5708" /><position name="left_shoulder_x_joint_position" joint="left_shoulder_x_joint" kp="800" ctrllimited="true" ctrlrange="-0.349066 3.49066" /><position name="left_shoulder_z_joint_position" joint="left_shoulder_z_joint" kp="800" ctrllimited="true" ctrlrange="-2.9671 2.9671" /><position name="left_elbow_joint_position" joint="left_elbow_joint" kp="800" ctrllimited="true" ctrlrange="-0.767945 1.74533" /><position name="right_shoulder_y_joint_position" joint="right_shoulder_y_joint" kp="800" ctrllimited="true" ctrlrange="-3.8397 1.5708" /><position name="right_shoulder_x_joint_position" joint="right_shoulder_x_joint" kp="800" ctrllimited="true" ctrlrange="-3.49066 0.349066" /><position name="right_shoulder_z_joint_position" joint="right_shoulder_z_joint" kp="800" ctrllimited="true" ctrlrange="-2.9671 2.9671" /><position name="right_elbow_joint_position" joint="right_elbow_joint" kp="800" ctrllimited="true" ctrlrange="-0.767945 1.74533" /><position name="left_hip_y_joint_position" joint="left_hip_y_joint" kp="800" ctrllimited="true" ctrlrange="-2.7925 1.5708" /><position name="left_hip_x_joint_position" joint="left_hip_x_joint" kp="800" ctrllimited="true" ctrlrange="-0.349066 2.618" /><position name="left_hip_z_joint_position" joint="left_hip_z_joint" kp="800" ctrllimited="true" ctrlrange="-0.5236 3.6652" /><position name="left_knee_joint_position" joint="left_knee_joint" kp="800" ctrllimited="true" ctrlrange="-0.17453 2.4958" /><position name="left_ankle_y_joint_position" joint="left_ankle_y_joint" kp="800" ctrllimited="true" ctrlrange="-1.0472 0.7854" /><position name="left_ankle_x_joint_position" joint="left_ankle_x_joint" kp="800" ctrllimited="true" ctrlrange="-0.61087 0.61087" /><position name="right_hip_y_joint_position" joint="right_hip_y_joint" kp="800" ctrllimited="true" ctrlrange="-2.7925 1.5708" /><position name="right_hip_x_joint_position" joint="right_hip_x_joint" kp="800" ctrllimited="true" ctrlrange="-2.618 0.349066" /><position name="right_hip_z_joint_position" joint="right_hip_z_joint" kp="800" ctrllimited="true" ctrlrange="-3.6652 0.5236" /><position name="right_knee_joint_position" joint="right_knee_joint" kp="800" ctrllimited="true" ctrlrange="-0.17453 2.4958" /><position name="right_ankle_y_joint_position" joint="right_ankle_y_joint" kp="800" ctrllimited="true" ctrlrange="-1.0472 0.7854" /><position name="right_ankle_x_joint_position" joint="right_ankle_x_joint" kp="800" ctrllimited="true" ctrlrange="-0.61087 0.61087" /></actuator><sensor><framequat name="imu_quat" objtype="site" objname="body_imu" /><gyro name="imu_ang_vel" site="body_imu" /><accelerometer name="imu_lin_acc" site="body_imu" /><velocimeter name="imu_lin_vel" site="body_imu" /><framezaxis name="imu_upvector" objtype="body" objname="world" reftype="site" refname="body_imu" /></sensor></mujoco>
