<mujoco model="go2_description">
  <compiler angle="radian"/>

  <worldbody>
    <body name="base">
      <inertial pos="0.0201531 0 -0.00510896" quat="-0.000484971 0.713304 -0.00161969 0.700853" mass="7.279" diaginertia="0.112836 0.103121 0.0257104"/>
      <joint name="floating_base_joint" type="free"/>
      <geom size="0.1881 0.04675 0.057" type="box"/>
      <geom size="0.05 0.045" pos="0.285 0 0.01" type="cylinder"/>
      <geom size="0.047" pos="0.293 0 -0.06"/>
      <body name="FL_hip" pos="0.1934 0.0465 0">
        <inertial pos="-0.004756 0.00171489 -9.28162e-05" quat="0.497627 0.500003 0.504441 0.497899" mass="0.767" diaginertia="0.000998282 0.00065837 0.000539924"/>
        <joint name="FL_hip_joint" pos="0 0 0" axis="1 0 0" range="-1.0472 1.0472" actuatorfrcrange="-23.7 23.7"/>
        <geom size="0.046 0.02" pos="0 0.08 0" quat="0.707107 0.707107 0 0" type="cylinder"/>
        <body name="FL_thigh" pos="0 0.0955 0">
          <inertial pos="-0.00115176 -0.0207007 -0.0303549" quat="0.622906 0.0767399 -0.0333173 0.777811" mass="1.241" diaginertia="0.00622804 0.00605116 0.00109601"/>
          <joint name="FL_thigh_joint" pos="0 0 0" axis="0 1 0" range="-1.5708 3.4907" actuatorfrcrange="-23.7 23.7"/>
          <geom size="0.1065 0.01225 0.017" pos="0 0 -0.1065" quat="0.707107 0 0.707107 0" type="box"/>
          <body name="FL_calf" pos="0 0 -0.213">
            <inertial pos="0.00629595 -0.000622121 -0.141417" quat="0.710672 0.00154099 -0.00450087 0.703508" mass="0.241352" diaginertia="0.0014901 0.00146356 5.31397e-05"/>
            <joint name="FL_calf_joint" pos="0 0 0" axis="0 1 0" range="-2.7227 -0.83776" actuatorfrcrange="-45.43 45.43"/>
            <geom size="0.012 0.06" pos="0.008 0 -0.06" quat="0.994493 0 -0.104807 0" type="cylinder"/>
            <geom size="0.011 0.0325" pos="0.02 0 -0.148" quat="0.999688 0 0.0249974 0" type="cylinder"/>
            <geom size="0.0155 0.015" pos="0.00801333 0 -0.18745" quat="0.965093 0 0.261909 0" type="cylinder"/>
            <geom size="0.022" pos="-0.002 0 -0.213"/>
          </body>
        </body>
      </body>
      <body name="FR_hip" pos="0.1934 -0.0465 0">
        <inertial pos="-0.00479081 -0.00171489 -9.28162e-05" quat="0.497915 0.504477 0.499987 0.497592" mass="0.767" diaginertia="0.000998028 0.000658115 0.000539924"/>
        <joint name="FR_hip_joint" pos="0 0 0" axis="1 0 0" range="-1.0472 1.0472" actuatorfrcrange="-23.7 23.7"/>
        <geom size="0.046 0.02" pos="0 -0.08 0" quat="0.707107 0.707107 0 0" type="cylinder"/>
        <body name="FR_thigh" pos="0 -0.0955 0">
          <inertial pos="-0.0057918 0.0207007 -0.0303549" quat="0.512281 -0.0184867 0.0761773 0.855233" mass="1.241" diaginertia="0.0062377 0.00598212 0.00107542"/>
          <joint name="FR_thigh_joint" pos="0 0 0" axis="0 1 0" range="-1.5708 3.4907" actuatorfrcrange="-23.7 23.7"/>
          <geom size="0.1065 0.01225 0.017" pos="0 0 -0.1065" quat="0.707107 0 0.707107 0" type="box"/>
          <body name="FR_calf" pos="0 0 -0.213">
            <inertial pos="0.00629595 0.000622121 -0.141417" quat="0.703508 -0.00450087 0.00154099 0.710672" mass="0.241352" diaginertia="0.0014901 0.00146356 5.31397e-05"/>
            <joint name="FR_calf_joint" pos="0 0 0" axis="0 1 0" range="-2.7227 -0.83776" actuatorfrcrange="-45.43 45.43"/>
            <geom size="0.013 0.06" pos="0.01 0 -0.06" quat="0.995004 0 -0.0998334 0" type="cylinder"/>
            <geom size="0.011 0.0325" pos="0.02 0 -0.148" quat="0.999688 0 0.0249974 0" type="cylinder"/>
            <geom size="0.0155 0.015" pos="0.00801333 0 -0.18745" quat="0.965093 0 0.261909 0" type="cylinder"/>
            <geom size="0.022" pos="-0.002 0 -0.213"/>
          </body>
        </body>
      </body>
      <body name="RL_hip" pos="-0.1934 0.0465 0">
        <inertial pos="0.00479081 0.00171489 -9.28162e-05" quat="0.504477 0.497915 0.497592 0.499987" mass="0.767" diaginertia="0.000998028 0.000658115 0.000539924"/>
        <joint name="RL_hip_joint" pos="0 0 0" axis="1 0 0" range="-1.0472 1.0472" actuatorfrcrange="-23.7 23.7"/>
        <geom size="0.046 0.02" pos="0 0.08 0" quat="0.707107 0.707107 0 0" type="cylinder"/>
        <body name="RL_thigh" pos="0 0.0955 0">
          <inertial pos="-0.00115176 -0.0207007 -0.0303549" quat="0.622906 0.0767399 -0.0333173 0.777811" mass="1.241" diaginertia="0.00622804 0.00605116 0.00109601"/>
          <joint name="RL_thigh_joint" pos="0 0 0" axis="0 1 0" range="-0.5236 4.5379" actuatorfrcrange="-23.7 23.7"/>
          <geom size="0.1065 0.01225 0.017" pos="0 0 -0.1065" quat="0.707107 0 0.707107 0" type="box"/>
          <body name="RL_calf" pos="0 0 -0.213">
            <inertial pos="0.00629595 -0.000622121 -0.141417" quat="0.710672 0.00154099 -0.00450087 0.703508" mass="0.241352" diaginertia="0.0014901 0.00146356 5.31397e-05"/>
            <joint name="RL_calf_joint" pos="0 0 0" axis="0 1 0" range="-2.7227 -0.83776" actuatorfrcrange="-45.43 45.43"/>
            <geom size="0.013 0.06" pos="0.01 0 -0.06" quat="0.995004 0 -0.0998334 0" type="cylinder"/>
            <geom size="0.011 0.0325" pos="0.02 0 -0.148" quat="0.999688 0 0.0249974 0" type="cylinder"/>
            <geom size="0.0155 0.015" pos="0.00801333 0 -0.18745" quat="0.965093 0 0.261909 0" type="cylinder"/>
            <geom size="0.022" pos="-0.002 0 -0.213"/>
          </body>
        </body>
      </body>
      <body name="RR_hip" pos="-0.1934 -0.0465 0">
        <inertial pos="0.004756 -0.00171489 -9.28162e-05" quat="0.500003 0.497627 0.497899 0.504441" mass="0.767" diaginertia="0.000998282 0.00065837 0.000539924"/>
        <joint name="RR_hip_joint" pos="0 0 0" axis="1 0 0" range="-1.0472 1.0472" actuatorfrcrange="-23.7 23.7"/>
        <geom size="0.046 0.02" pos="0 -0.08 0" quat="0.707107 0.707107 0 0" type="cylinder"/>
        <body name="RR_thigh" pos="0 -0.0955 0">
          <inertial pos="-0.0057918 0.0207007 -0.0303549" quat="0.512281 -0.0184867 0.0761773 0.855233" mass="1.241" diaginertia="0.0062377 0.00598212 0.00107542"/>
          <joint name="RR_thigh_joint" pos="0 0 0" axis="0 1 0" range="-0.5236 4.5379" actuatorfrcrange="-23.7 23.7"/>
          <geom size="0.1065 0.01225 0.017" pos="0 0 -0.1065" quat="0.707107 0 0.707107 0" type="box"/>
          <body name="RR_calf" pos="0 0 -0.213">
            <inertial pos="0.00629595 0.000622121 -0.141417" quat="0.703508 -0.00450087 0.00154099 0.710672" mass="0.241352" diaginertia="0.0014901 0.00146356 5.31397e-05"/>
            <joint name="RR_calf_joint" pos="0 0 0" axis="0 1 0" range="-2.7227 -0.83776" actuatorfrcrange="-45.43 45.43"/>
            <geom size="0.013 0.06" pos="0.01 0 -0.06" quat="0.995004 0 -0.0998334 0" type="cylinder"/>
            <geom size="0.011 0.0325" pos="0.02 0 -0.148" quat="0.999688 0 0.0249974 0" type="cylinder"/>
            <geom size="0.0155 0.015" pos="0.00801333 0 -0.18745" quat="0.965093 0 0.261909 0" type="cylinder"/>
            <geom size="0.022" pos="-0.002 0 -0.213"/>
          </body>
        </body>
      </body>
    </body>
  </worldbody>
</mujoco>
